Workbook
Name L_Adjust: #REF!
Name L_AJE_Tot: #REF!
Name L_CY_Beg: #REF!
Name L_CY_End: #REF!
Name L_PY_End: #REF!
Name L_RJE_Tot: #REF!
Name S_Adjust_Data: #REF!
Name S_AJE_Tot_Data: #REF!
Name S_CY_Beg_Data: #REF!
Name S_CY_End_Data: #REF!
Name S_PY_End_Data: #REF!
Name S_RJE_Tot_Data: #REF!
Name TextRefCopy201: #REF!

Sheet Claude Log
A1: Turn # | B1: Date | C1: User Request | D1: Action Taken | E1: Details | F1: Outcome
A2: 1 | B2: 46078 | C2: Add data from 7 remaining site sheets (YJ, BD, AGJ, GS, YDP, YS, BP) into the Master sheet after row 159 | D2: Wrote 17 data rows to Master rows 160–176 with matching formatting and borders | E2: Sites added: YJ (6 rows), BD (5 rows), AGJ (1 row), GS (1 row), YDP (2 rows), YS (1 row), BP (1 row). All data pulled from existing individual site sheets. Applied Arial 11pt, center-aligned, thin/medium borders matching existing Master style. BP row 176 has medium bottom border as the new last row. | F2: Master sheet now contains all 20 sites (rows 5–176). Data and formatting verified correct.
A3: 2 | B3: 46078 | C3: Add data from 4 more site sheets (CSL, SEG, S51, KD) into the Master sheet after row 176 | D3: Wrote 23 data rows to Master rows 177–199 with matching formatting and borders | E3: Sites added: CSL (7 rows: G0001→G1110, OG03, 2000→2373, 3003→3281, 4002→4260, A3000→A3180, W3000→W3019), SEG (3 rows: G1001→G1403, 1001→1685, A1201→A1608), S51 (11 rows incl Drive Up units L1001→L1106, T1001→T1006, B1001→B1069), KD (2 rows: 3001→3220, 5001→5334). Also fixed BP row 176 bottom border from medium to thin. KD row 199 has medium bottom border as the new last row. | F3: Master sheet now contains all 24 sites (rows 5–199). All data and formatting verified.
A4: 3 | B4: 46078 | C4: Remove 'ONLY FOR SUMMER' qualifier from Storage Type and Dehumidifier columns in rows 160–176 (YJ, BD, AGJ, GS, YDP, YS, BP sites) | D4: Updated G160:H176 — changed 'AIR-CON, ONLY FOR SUMMER' → 'AIR-CON' and 'YES, ONLY FOR SUMMER' → 'YES' | E4: By convention, even seasonal air-con is classified as AIR-CON. Affected 16 cells in col G and 5 cells in col H. YDP row 174 (NON AIR-CON) was left unchanged in col G but its dehumidifier was also cleaned to just 'YES'. | F4: Rows 160–176 now use clean AIR-CON / YES / NO values without seasonal qualifiers.

Sheet SiteConfig
A1: Facility | B1: Internal Label | C1: SiteCode | D1: Name | E1: District
A2: AMK | B2: AMK | C2: L018 | D2: Extra Space AMK Pte Ltd | E2: Ang Mo Kio
A3: BK | B3: BKR (BK) | C3: L002 | D3: Extra Space Pte Ltd | E3: Boon Keng
A4: CW | B4: CW | C4: L029 | D4: Extra Space Commonwealth Pte Ltd | E4: Commonwealth
A5: CW1 | B5: CW1 | C5: L028 | D5: Extra Space Commonwealth Pte Ltd | E5: Commonwealth
A6: EL | B6: ELK (EL) | C6: L003 | D6: Extra Space Eunos Link | E6: Kaki Bukit
A7: HV | B7: HV | C7: L025 | D7: Extra Space Hillview Pte Ltd | E7: Hillview
A8: IMM | B8: IMM | C8: L001 | D8: Extra Space Jurong Pte Ltd | E8: Jurong East
A9: KW | B9: KWY (KW) | C9: L008 | D9: Extra Space Kallang Way | E9: Kallang
A10: MMR | B10: MMR | C10: L005 | D10: Extra Space Marymount | E10: Sin Ming
A11: TP | B11: TPY (TP) | C11: L022 | D11: Extra Space Toa Payoh | E11: Toa Payoh
A12: TS | B12: TS | C12: L030 | D12: Extra Space Tai Seng Pte Ltd | E12: Tai Seng
... A25: BP | B25: ESKBP | C25: L024 | D25: Extra Space - Banpo | E25: Seocho-gu, Seoul

Sheet Master
A3: Internal Name | B3: Sitecode | C3: S/N | D3: UNITS Name Range | G3: STORAGE TYPE | H3: Climate Type | I3: DEHUMIDIFER | J3: NOKE
I4: YES / NO | J4: YES / NO
A5: WD | B5: =VLOOKUP(A5,SiteConfig!$A:$C,3,FALSE) -> L017 | C5: 1 | D5: A3002 | E5: TO | F5: A3076 | H5: AIR-CON | I5: YES | J5: NO
A6: WD | B6: =VLOOKUP(A6,SiteConfig!$A:$C,3,FALSE) -> L017 | C6: 2 | D6: A4200 | E6: TO | F6: A4217 | H6: AIR-CON | I6: NO | J6: NO
A7: WD | B7: =VLOOKUP(A7,SiteConfig!$A:$C,3,FALSE) -> L017 | C7: 3 | D7: A4300 | E7: TO | F7: A4314 | H7: AIR-CON | I7: NO | J7: NO
A8: WD | B8: =VLOOKUP(A8,SiteConfig!$A:$C,3,FALSE) -> L017 | C8: 4 | D8: 4000 | E8: TO | F8: 4020 | H8: NON AIR-CON | I8: NO | J8: NO
A9: WD | B9: =VLOOKUP(A9,SiteConfig!$A:$C,3,FALSE) -> L017 | C9: 5 | D9: A4500 | E9: TO | F9: A4518 | H9: AIR-CON | I9: NO | J9: NO
A10: WD | B10: =VLOOKUP(A10,SiteConfig!$A:$C,3,FALSE) -> L017 | C10: 6 | D10: A4000 | E10: TO | F10: A4049 | H10: AIR-CON | I10: YES | J10: NO
A11: WD | B11: =VLOOKUP(A11,SiteConfig!$A:$C,3,FALSE) -> L017 | C11: 7 | D11: 4200 | E11: TO | F11: 4223 | H11: NON AIR-CON | I11: NO | J11: NO
A12: WD | B12: =VLOOKUP(A12,SiteConfig!$A:$C,3,FALSE) -> L017 | C12: 8 | D12: A4100 | E12: TO | F12: A4113 | H12: AIR-CON | I12: YES | J12: NO
A13: WD | B13: =VLOOKUP(A13,SiteConfig!$A:$C,3,FALSE) -> L017 | C13: 9 | D13: 4100 | E13: TO | F13: 4132 | H13: NON AIR-CON | I13: YES | J13: NO
A14: WD | B14: =VLOOKUP(A14,SiteConfig!$A:$C,3,FALSE) -> L017 | C14: 10 | D14: 6001 | E14: TO | F14: 6183 | H14: NON AIR-CON | I14: NO | J14: NO
A15: TP | B15: =VLOOKUP(A15,SiteConfig!$A:$C,3,FALSE) -> L022 | C15: 1 | D15: A2001 | E15: TO | F15: A2102 | H15: AIR-CON | I15: NO | J15: NO
A16: TP | B16: =VLOOKUP(A16,SiteConfig!$A:$C,3,FALSE) -> L022 | C16: 2 | D16: W2001 | E16: TO | F16: W2098 | G16: W or WL | H16: Refrigerated | I16: NO | J16: NO
A17: TP | B17: =VLOOKUP(A17,SiteConfig!$A:$C,3,FALSE) -> L022 | C17: 3 | D17: S2201 | E17: TO | F17: S2272 | H17: Non AIR-CON | I17: NO | J17: NO
A18: TP | B18: =VLOOKUP(A18,SiteConfig!$A:$C,3,FALSE) -> L022 | C18: 4 | D18: S3000 | E18: TO | F18: S3087 | H18: Non AIR-CON | I18: NO | J18: NO
A19: TP | B19: =VLOOKUP(A19,SiteConfig!$A:$C,3,FALSE) -> L022 | C19: 5 | D19: A30001 | E19: TO | F19: A30117 | H19: AIR-CON | I19: NO | J19: NO
A20: TP | B20: =VLOOKUP(A20,SiteConfig!$A:$C,3,FALSE) -> L022 | C20: 6 | D20: S4001 | E20: TO | F20: S4022 | H20: Non AIR-CON | I20: NO | J20: NO
A21: TP | B21: =VLOOKUP(A21,SiteConfig!$A:$C,3,FALSE) -> L022 | C21: 7 | D21: S5001 | E21: TO | F21: S5163 | H21: Non AIR-CON | I21: NO | J21: NO
A22: TP | B22: =VLOOKUP(A22,SiteConfig!$A:$C,3,FALSE) -> L022 | C22: 8 | D22: S6001 | E22: TO | F22: S6179 | H22: Non AIR-CON | I22: NO | J22: NO
A23: BK | B23: =VLOOKUP(A23,SiteConfig!$A:$C,3,FALSE) -> L002 | C23: 1 | D23: 1001 | E23: TO | F23: 1527 | H23: NON AIR-CON | I23: NO | J23: NO
A24: BK | B24: =VLOOKUP(A24,SiteConfig!$A:$C,3,FALSE) -> L002 | C24: 2 | D24: W1121 | E24: TO | F24: W1563 | G24: W or WL | H24: Refrigerated | I24: NO | J24: NO
A25: BK | B25: =VLOOKUP(A25,SiteConfig!$A:$C,3,FALSE) -> L002 | C25: 3 | D25: 2001 | E25: TO | F25: 2143 | H25: Climate Controlled | I25: NO | J25: NO
A26: BK | B26: =VLOOKUP(A26,SiteConfig!$A:$C,3,FALSE) -> L002 | C26: 4 | D26: 3000 | E26: TO | F26: 3136 | H26: AIR-CON | I26: NO | J26: NO
A27: BK | B27: =VLOOKUP(A27,SiteConfig!$A:$C,3,FALSE) -> L002 | C27: 5 | D27: A3000 | E27: TO | F27: A3066 | H27: AIR-CON | I27: NO | J27: NO
A28: BK | B28: =VLOOKUP(A28,SiteConfig!$A:$C,3,FALSE) -> L002 | C28: 6 | D28: W3001 | E28: TO | F28: W3071 | G28: W or WL | H28: Refrigerated | I28: NO | J28: NO
A29: BK | B29: =VLOOKUP(A29,SiteConfig!$A:$C,3,FALSE) -> L002 | C29: 7 | D29: 4001 | E29: TO | F29: 4211 | H29: AIR-CON | I29: NO | J29: NO
A30: BK | B30: =VLOOKUP(A30,SiteConfig!$A:$C,3,FALSE) -> L002 | C30: 8 | D30: W4001 | E30: TO | F30: W4061 | G30: W or WL | H30: Refrigerated | I30: NO | J30: NO
A31: BK | B31: =VLOOKUP(A31,SiteConfig!$A:$C,3,FALSE) -> L002 | C31: 9 | D31: 5000C | E31: TO | F31: 5178 | H31: AIR-CON | I31: NO | J31: NO
A32: BK | B32: =VLOOKUP(A32,SiteConfig!$A:$C,3,FALSE) -> L002 | C32: 10 | D32: A5000 | E32: TO | F32: A5062 | H32: AIR-CON | I32: NO | J32: NO
A33: BK | B33: =VLOOKUP(A33,SiteConfig!$A:$C,3,FALSE) -> L002 | C33: 11 | D33: 5000D | E33: TO | F33: 5000V | H33: NON AIR-CON | I33: NO | J33: NO
A34: BK | B34: =VLOOKUP(A34,SiteConfig!$A:$C,3,FALSE) -> L002 | C34: 12 | D34: W5179 | E34: TO | F34: W5308 | G34: W or WL | H34: Refrigerated | I34: NO | J34: NO
A35: BK | B35: =VLOOKUP(A35,SiteConfig!$A:$C,3,FALSE) -> L002 | C35: 13 | D35: 6000 | E35: TO | F35: 6276 | H35: Climate Controlled | I35: NO | J35: NO
A36: BK | B36: =VLOOKUP(A36,SiteConfig!$A:$C,3,FALSE) -> L002 | C36: 14 | D36: 7001 | E36: TO | F36: 7097G | H36: AIR-CON | I36: NO | J36: NO
A37: BK | B37: =VLOOKUP(A37,SiteConfig!$A:$C,3,FALSE) -> L002 | C37: 15 | D37: A7001 | E37: TO | F37: A7090 | H37: AIR-CON | I37: NO | J37: NO
A38: BK | B38: =VLOOKUP(A38,SiteConfig!$A:$C,3,FALSE) -> L002 | C38: 16 | D38: W7001 | E38: TO | F38: W7071 | G38: W or WL | H38: Refrigerated | I38: NO | J38: NO
A39: CW | B39: =VLOOKUP(A39,SiteConfig!$A:$C,3,FALSE) -> L029 | C39: 1 | D39: A1100 | E39: To | F39: A1142 | G39: Executive | H39: Aircon | I39: No | J39: Yes
A40: CW | B40: =VLOOKUP(A40,SiteConfig!$A:$C,3,FALSE) -> L029 | C40: 2 | D40: A1800 | E40: To | F40: A1833 | H40: Aircon | I40: No | J40: Yes
A41: CW | B41: =VLOOKUP(A41,SiteConfig!$A:$C,3,FALSE) -> L029 | C41: 3 | D41: A2100 | E41: To | F41: A2157 | G41: Executive | H41: Aircon | I41: No | J41: Yes
A42: CW | B42: =VLOOKUP(A42,SiteConfig!$A:$C,3,FALSE) -> L029 | C42: 4 | D42: A2700 | E42: To | F42: A2743 | H42: Aircon | I42: Yes | J42: Entrance Only
...

Sheet WDL
B3: STORAGE UNITS DESCRIPTION IN WOODLANDS CLOSE
A5: Internal Name | B5: S/N | C5: UNITS Name Range | F5: STORAGE TYPE | G5: Climate Type | H5: DEHUMIDIFER | I5: NOKE
H6: YES / NO | I6: YES / NO
A7: WDL | B7: 1 | C7: A3002 | D7: TO | E7: A3076 | G7: AIR-CON | H7: YES | I7: NO
A8: WDL | B8: 2 | C8: A4200 | D8: TO | E8: A4217 | G8: AIR-CON | H8: NO | I8: NO
A9: WDL | B9: 3 | C9: A4300 | D9: TO | E9: A4314 | G9: AIR-CON | H9: NO | I9: NO
A10: WDL | B10: 4 | C10: 4000 | D10: TO | E10: 4020 | G10: NON AIR-CON | H10: NO | I10: NO
A11: WDL | B11: 5 | C11: A4500 | D11: TO | E11: A4518 | G11: AIR-CON | H11: NO | I11: NO
A12: WDL | B12: 6 | C12: A4000 | D12: TO | E12: A4049 | G12: AIR-CON | H12: YES | I12: NO
A13: WDL | B13: 7 | C13: 4200 | D13: TO | E13: 4223 | G13: NON AIR-CON | H13: NO | I13: NO
A14: WDL | B14: 8 | C14: A4100 | D14: TO | E14: A4113 | G14: AIR-CON | H14: YES | I14: NO
A15: WDL | B15: 9 | C15: 4100 | D15: TO | E15: 4132 | G15: NON AIR-CON | H15: YES | I15: NO
A16: WDL | B16: 10 | C16: 6001 | D16: TO | E16: 6183 | G16: NON AIR-CON | H16: NO | I16: NO

Sheet TPY
B3: STORAGE UNITS DESCRIPTION IN TOA PAYOH
A5: Internal Name | B5: S/N | C5: UNITS Name Range | F5: STORAGE TYPE | G5: Climate Type | H5: DEHUMIDIFER | I5: NOKE
H6: YES / NO | I6: YES / NO
A7: TPY | B7: 1 | C7: A2001 | D7: TO | E7: A2102 | G7: AIR-CON | H7: NO | I7: NO
A8: TPY | B8: 2 | C8: W2001 | D8: TO | E8: W2098 | F8: W or WL | G8: Refrigerated | H8: NO | I8: NO
A9: TPY | B9: 3 | C9: S2201 | D9: TO | E9: S2272 | G9: Non AIR-CON | H9: NO | I9: NO
A10: TPY | B10: 4 | C10: S3000 | D10: TO | E10: S3087 | G10: Non AIR-CON | H10: NO | I10: NO
A11: TPY | B11: 5 | C11: A30001 | D11: TO | E11: A30117 | G11: AIR-CON | H11: NO | I11: NO
A12: TPY | B12: 6 | C12: S4001 | D12: TO | E12: S4022 | G12: Non AIR-CON | H12: NO | I12: NO
A13: TPY | B13: 7 | C13: S5001 | D13: TO | E13: S5163 | G13: Non AIR-CON | H13: NO | I13: NO
A14: TPY | B14: 8 | C14: S6001 | D14: TO | E14: S6179 | G14: Non AIR-CON | H14: NO | I14: NO

Sheet BKR
B3: STORAGE UNITS DESCRIPTION IN BOON KENG
A5: Internal Name | B5: S/N | C5: UNITS Name Range | F5: STORAGE TYPE | G5: Climate Type | H5: DEHUMIDIFER | I5: NOKE
H6: YES / NO | I6: YES / NO
A7: BKR | B7: 1 | C7: 1001 | D7: TO | E7: 1527 | G7: NON AIR-CON | H7: NO | I7: NO
A8: BKR | B8: 2 | C8: W1121 | D8: TO | E8: W1563 | F8: W or WL | G8: Refrigerated | H8: NO | I8: NO
A9: BKR | B9: 3 | C9: 2001 | D9: TO | E9: 2143 | G9: Climate Controlled | H9: NO | I9: NO
A10: BKR | B10: 4 | C10: 3000 | D10: TO | E10: 3136 | G10: AIR-CON | H10: NO | I10: NO
A11: BKR | B11: 5 | C11: A3000 | D11: TO | E11: A3066 | G11: AIR-CON | H11: NO | I11: NO
A12: BKR | B12: 6 | C12: W3001 | D12: TO | E12: W3071 | F12: W or WL | G12: Refrigerated | H12: NO | I12: NO
A13: BKR | B13: 7 | C13: 4001 | D13: TO | E13: 4211 | G13: AIR-CON | H13: NO | I13: NO
A14: BKR | B14: 8 | C14: W4001 | D14: TO | E14: W4061 | F14: W or WL | G14: Refrigerated | H14: NO | I14: NO
A15: BKR | B15: 9 | C15: 5000C | D15: TO | E15: 5178 | G15: AIR-CON | H15: NO | I15: NO
A16: BKR | B16: 10 | C16: A5000 | D16: TO | E16: A5062 | G16: AIR-CON | H16: NO | I16: NO
A17: BKR | B17: 11 | C17: 5000D | D17: TO | E17: 5000V | G17: NON AIR-CON | H17: NO | I17: NO
A18: BKR | B18: 12 | C18: W5179 | D18: TO | E18: W5308 | F18: W or WL | G18: Refrigerated | H18: NO | I18: NO
A19: BKR | B19: 13 | C19: 6000 | D19: TO | E19: 6276 | G19: Climate Controlled | H19: NO | I19: NO
A20: BKR | B20: 14 | C20: 7001 | D20: TO | E20: 7097G | G20: AIR-CON | H20: NO | I20: NO
A21: BKR | B21: 15 | C21: A7001 | D21: TO | E21: A7090 | G21: AIR-CON | H21: NO | I21: NO
A22: BKR | B22: 16 | C22: W7001 | D22: TO | E22: W7071 | F22: W or WL | G22: Refrigerated | H22: NO | I22: NO

Sheet CW
B1: STORAGE UNIT DESCRIPTION (COMMONWEALTH)
A2: Internal Name | B2: S/N | C2: UNITS Name Range | F2: STORAGE TYPE | G2: Climate Type | H2: DEHUMIDIFER | I2: NOKE
H3: YES / NO | I3: YES / NO
A4: CW | B4: 1 | C4: A1100 | D4: To | E4: A1142 | F4: Executive | G4: Aircon | H4: No | I4: Yes
A5: CW | B5: 2 | C5: A1800 | D5: To | E5: A1833 | G5: Aircon | H5: No | I5: Yes
A6: CW | B6: 3 | C6: A2100 | D6: To | E6: A2157 | F6: Executive | G6: Aircon | H6: No | I6: Yes
A7: CW | B7: 4 | C7: A2700 | D7: To | E7: A2743 | G7: Aircon | H7: Yes | I7: Entrance Only / Units using Padlock
A8: CW | B8: 5 | C8: A2800 | D8: To | E8: A2866 | G8: Aircon | H8: Yes | I8: Entrance Only
A9: CW | B9: 6 | C9: A2900 | D9: To | E9: A2977 | G9: Aircon | H9: No | I9: Yes
A10: CW | B10: 7 | C10: A3300 | D10: To | E10: A3337 | G10: Aircon | H10: Yes | I10: Entrance Only / Units using Padlock
A11: CW | B11: 8 | C11: A3800 | D11: To | E11: A3860 | G11: Aircon | H11: Yes | I11: Entrance Only / Units using Padlock
A12: CW | B12: 9 | C12: W1600 | D12: To | E12: W1737 | G12: Wine | H12: No | I12: Entrance Only / Units using Padlock
A13: CW | B13: 10 | C13: W1800 | D13: To | E13: W1902 | G13: Wine | H13: No | I13: Yes

Sheet HV
B1: STORAGE UNIT DESCRIPTION (HILLVIEW)
A2: Internal Name | B2: S/N | C2: UNITS Name Range | F2: STORAGE TYPE | G2: Climate Type | H2: DEHUMIDIFER | I2: NOKE
H3: YES / NO | I3: YES / NO
A4: HV | B4: 1 | C4: 4000 | D4: To | E4: 4026 | G4: Non-Aircon | H4: No | I4: No
A5: HV | B5: 2 | C5: 4100 | D5: To | E5: 4121 | G5: Non-Aircon | H5: No | I5: No
A6: HV | B6: 3 | C6: 4200 | D6: To | E6: 4215 | G6: Non-Aircon | H6: No | I6: No
A7: HV | B7: 4 | C7: 4300 | D7: To | E7: 4330 | G7: Non-Aircon | H7: No | I7: Yes
A8: HV | B8: 5 | C8: 4400 | D8: To | E8: 4480 | G8: Non-Aircon | H8: No | I8: No
A9: HV | B9: 6 | C9: 8000 | D9: To | E9: 8033 | G9: Non-Aircon | H9: No | I9: No
A10: HV | B10: 7 | C10: 8100 | D10: To | E10: 8185 | G10: Non-Aircon | H10: No | I10: No
A11: HV | B11: 8 | C11: 8300 | D11: To | E11: 8316 | G11: Non-Aircon | H11: No | I11: No
A12: HV | B12: 9 | C12: 8400 | D12: To | E12: 8428 | G12: Non-Aircon | H12: No | I12: No
A13: HV | B13: 10 | C13: 8500 | D13: To | E13: 8531 | G13: Non-Aircon | H13: No | I13: No
A14: HV | B14: 11 | C14: A4500 | D14: To | E14: A4569 | G14: Aircon | H14: No | I14: No
A15: HV | B15: 12 | C15: A4700 | D15: To | E15: A4744 | G15: Aircon | H15: No | I15: No
A16: HV | B16: 13 | C16: A8200 | D16: To | E16: A8267 | G16: Aircon | H16: No | I16: No
B18: HV has 2 portable dehumidifiers that we will shift around different areas when needed.

Sheet IMM
B1: STORAGE UNIT DESCRIPTION (IMM)
A2: Internal Name | B2: S/N | C2: UNITS Name Range | F2: STORAGE TYPE | G2: Climate Type | H2: DEHUMIDIFER | I2: NOKE
H3: YES / NO | I3: YES / NO
A4: IMM | B4: 1 | C4: 2000 | D4: To | E4: 2088 | G4: Non-Aircon | H4: No | I4: No
A5: IMM | B5: 2 | C5: 2100 | D5: To | E5: 2257 | G5: Non-Aircon | H5: No | I5: No
A6: IMM | B6: 3 | C6: 3001 | D6: To | E6: 3311 | G6: Non-Aircon | H6: No | I6: No
A7: IMM | B7: 4 | C7: 4001 | D7: To | E7: 4087 | G7: Non-Aircon | H7: No | I7: No
A8: IMM | B8: 5 | C8: 5000A | D8: To | E8: 5224A | G8: Non-Aircon | H8: No | I8: No
A9: IMM | B9: 6 | C9: 6001 | D9: To | E9: 6091D | G9: Non-Aircon | H9: No | I9: No
A10: IMM | B10: 7 | C10: 7001 | D10: To | E10: 7213 | G10: Non-Aircon | H10: No | I10: No
A11: IMM | B11: 8 | C11: 8000 | D11: To | E11: 8141 | G11: Non-Aircon | H11: No | I11: No
A12: IMM | B12: 9 | C12: A5209 | D12: To | E12: A5265 | G12: Aircon | H12: No | I12: No
B14: IMM having centralised aircon during office hours

Sheet WC
B1: STORAGE UNIT DESCRIPTION (WEST COAST)
A2: Internal Name | B2: S/N | C2: UNITS Name Range | F2: STORAGE TYPE | G2: Climate Type | H2: DEHUMIDIFER | I2: NOKE
H3: YES / NO | I3: YES / NO
A4: WC | B4: 1 | C4: 1000 | D4: To | E4: 1109 | G4: Non-Aircon | H4: No | I4: No
A5: WC | B5: 2 | C5: 1200 | D5: To | E5: 1281 | G5: Non-Aircon | H5: No | I5: No
A6: WC | B6: 3 | C6: 1300 | D6: To | E6: 1391 | G6: Non-Aircon | H6: No | I6: No
A7: WC | B7: 4 | C7: 4000 | D7: To | E7: 4218 | G7: Non-Aircon | H7: No | I7: No
A8: WC | B8: 5 | C8: A4000 | D8: To | E8: A4120 | G8: Aircon | H8: No | I8: No

Sheet ELK
B3: STORAGE UNITS DESCRIPTION IN EUNOS LINK
A5: Internal Name | B5: S/N | C5: UNITS Name Range | F5: STORAGE TYPE | G5: Climate Type | H5: DEHUMIDIFER | I5: NOKE
H6: YES / NO | I6: YES / NO
A7: ELK | B7: 1 | C7: 1001 | D7: TO | E7: 1030 | F7: Drive UP | G7: NON AIR-CON | H7: NO | I7: NO
A8: ELK | B8: 2 | C8: 12001 | D8: TO | E8: 12052 | G8: NON AIR-CON | H8: NO | I8: NO
A9: ELK | B9: 3 | C9: 13001 | D9: TO | E9: 13068 | G9: NON AIR-CON | H9: NO | I9: NO
A10: ELK | B10: 4 | C10: 14001 | D10: TO | E10: 14027 | G10: NON AIR-CON | H10: NO | I10: NO
A11: ELK | B11: 5 | C11: 15001 | D11: TO | E11: 15064 | G11: NON AIR-CON | H11: NO | I11: NO
A12: ELK | B12: 6 | C12: 16001 | D12: TO | E12: 16053 | G12: NON AIR-CON | H12: NO | I12: NO
A13: ELK | B13: 7 | C13: A1001 | D13: TO | E13: A1162 | G13: AIR-CON | H13: NO | I13: NO
A14: ELK | B14: 8 | C14: W5000 | D14: TO | E14: W5042 | F14: W or WL | G14: Refrigerated | H14: NO | I14: NO
A15: ELK | B15: 9 | C15: 21001 | D15: TO | E15: 21013 | G15: NON AIR-CON | H15: NO | I15: NO
A16: ELK | B16: 10 | C16: 22001 | D16: TO | E16: 22026 | G16: NON AIR-CON | H16: NO | I16: NO
A17: ELK | B17: 11 | C17: 23001 | D17: TO | E17: 23086 | G17: NON AIR-CON | H17: NO | I17: NO
A18: ELK | B18: 12 | C18: 24001 | D18: TO | E18: 24206 | G18: NON AIR-CON | H18: NO | I18: NO
A19: ELK | B19: 13 | C19: 25001 | D19: TO | E19: 25126 | G19: NON AIR-CON | H19: NO | I19: NO
A20: ELK | B20: 14 | C20: 27001 | D20: TO | E20: 27032 | G20: NON AIR-CON | H20: NO | I20: NO
A21: ELK | B21: 15 | C21: 28001 | D21: TO | E21: 28013 | G21: NON AIR-CON | H21: NO | I21: NO
A22: ELK | B22: 16 | C22: A2001 | D22: TO | E22: A2113 | G22: AIR-CON | H22: NO | I22: NO
A23: ELK | B23: 17 | C23: 32001 | D23: TO | E23: 32026 | G23: NON AIR-CON | H23: NO | I23: NO
A24: ELK | B24: 18 | C24: 33001 | D24: TO | E24: 33095 | G24: NON AIR-CON | H24: NO | I24: NO
A25: ELK | B25: 19 | C25: 34001 | D25: TO | E25: 34107 | G25: NON AIR-CON | H25: NO | I25: NO
A26: ELK | B26: 20 | C26: 35001 | D26: TO | E26: 35119 | G26: NON AIR-CON | H26: NO | I26: NO
A27: ELK | B27: 21 | C27: 36001 | D27: TO | E27: 36104 | G27: NON AIR-CON | H27: NO | I27: NO
A28: ELK | B28: 22 | C28: 37001 | D28: TO | E28: 37043 | G28: NON AIR-CON | H28: NO | I28: NO
A29: ELK | B29: 23 | C29: A3000 | D29: TO | E29: A3064 | G29: AIR-CON | H29: NO | I29: NO
A30: ELK | B30: 24 | C30: W3001 | D30: TO | E30: W3040 | F30: W or WL | G30: Refrigerated | H30: NO | I30: NO
A31: ELK | B31: 25 | C31: 42001 | D31: TO | E31: 42021 | G31: NON AIR-CON | H31: NO | I31: NO
A32: ELK | B32: 26 | C32: 43001 | D32: TO | E32: 43060 | G32: NON AIR-CON | H32: NO | I32: NO
A33: ELK | B33: 27 | C33: 44001 | D33: TO | E33: 44046 | G33: NON AIR-CON | H33: NO | I33: NO
A34: ELK | B34: 28 | C34: 45001 | D34: TO | E34: 45113 | G34: NON AIR-CON | H34: NO | I34: NO
A35: ELK | B35: 29 | C35: 46001 | D35: TO | E35: 46076 | G35: NON AIR-CON | H35: NO | I35: NO
A36: ELK | B36: 30 | C36: 47001 | D36: TO | E36: 47022 | G36: NON AIR-CON | H36: NO | I36: NO
A37: ELK | B37: 31 | C37: 48000 | D37: TO | E37: 48011 | G37: NON AIR-CON | H37: NO | I37: NO
A38: ELK | B38: 32 | C38: 48101 | D38: TO | E38: 48108 | G38: NON AIR-CON | H38: NO | I38: NO
A39: ELK | B39: 33 | C39: 48200 | D39: TO | E39: 48214 | G39: NON AIR-CON | H39: NO | I39: NO
A40: ELK | B40: 34 | C40: 48300 | D40: TO | E40: 48312 | G40: NON AIR-CON | H40: NO | I40: NO
A41: ELK | B41: 35 | C41: 48401 | D41: TO | E41: 48407 | G41: NON AIR-CON | H41: NO | I41: NO
A42: ELK | B42: 36 | C42: 48500 | D42: TO | E42: 48518 | G42: NON AIR-CON | H42: NO | I42: NO

Sheet AMK
B3: STORAGE UNITS DESCRIPTION IN Ang Mo Kio
A5: Internal Name | B5: S/N | C5: UNITS Name Range | F5: STORAGE TYPE | G5: Climate Type | H5: DEHUMIDIFER | I5: NOKE
H6: YES / NO | I6: YES / NO
A7: AMK | B7: 1 | C7: D1000 | D7: TO | E7: D1006 | F7: Drive UP | G7: NON AIR-CON | H7: NO | I7: NO
A8: AMK | B8: 2 | C8: 1100 | D8: TO | E8: 1140 | G8: NON AIR-CON | H8: YES | I8: YES
A9: AMK | B9: 3 | C9: 1001 | D9: TO | E9: 1009 | G9: NON AIR-CON | H9: NO | I9: NO
A10: AMK | B10: 4 | C10: 1200 | D10: TO | E10: 1226 | G10: NON AIR-CON | H10: NO | I10: NO
A11: AMK | B11: 5 | C11: 2001 | D11: TO | E11: 2132 | G11: NON AIR-CON | H11: NO | I11: NO
A12: AMK | B12: 6 | C12: 2200 | D12: TO | E12: 2227 | G12: NON AIR-CON | H12: NO | I12: NO
A13: AMK | B13: 7 | C13: 2301 | D13: TO | E13: 2410 | G13: NON AIR-CON | H13: NO | I13: NO
A14: AMK | B14: 8 | C14: 2501 | D14: TO | E14: 2604 | G14: NON AIR-CON | H14: NO | I14: NO
A15: AMK | B15: 9 | C15: 2700 | D15: TO | E15: 2734 | G15: NON AIR-CON | H15: NO | I15: NO
A16: AMK | B16: 10 | C16: 2800 | D16: TO | E16: 2814 | G16: NON AIR-CON | H16: NO | I16: NO
A17: AMK | B17: 11 | C17: 2998 &2998A | D17: TO | E17: 2998L | G17: NON AIR-CON | H17: NO | I17: NO
A18: AMK | B18: 12 | C18: A2000 | D18: TO | E18: A2086 | G18: AIRCON | H18: YES | I18: NO
A19: AMK | B19: 13 | C19: P2000 | D19: TO | E19: P2029 | G19: AIRCON / Premium | H19: YES | I19: NO
A20: AMK | B20: 14 | C20: 3000 | D20: TO | E20: 3048 | G20: NON AIR-CON | H20: YES | I20: NO
A21: AMK | B21: 15 | C21: 3100 | D21: TO | E21: 3156 | G21: NON AIR-CON | H21: NO | I21: NO
A22: AMK | B22: 16 | C22: 3500 | D22: TO | E22: 3597 | G22: NON AIR-CON | H22: NO | I22: NO
A23: AMK | B23: 17 | C23: 3600 | D23: TO | E23: 3600 | G23: NON AIR-CON | H23: NO | I23: NO
A24: AMK | B24: 18 | C24: A3000 | D24: TO | E24: A3038 | G24: AIRCON | H24: NO | I24: NO
A25: AMK | B25: 19 | C25: A3300 | D25: TO | E25: A3372 | G25: AIRCON | H25: NO | I25: NO
A26: AMK | B26: 20 | C26: E3000 | D26: TO | E26: E3048 | G26: AIRCON / Executive | H26: NO | I26: NO
A27: AMK | B27: 21 | C27: 4001 | D27: TO | E27: 4187 | G27: NON AIR-CON | H27: NO | I27: NO

Sheet MMR
B3: STORAGE UNITS DESCRIPTION IN MARYMOUNT
A5: Internal Name | B5: S/N | C5: UNITS Name Range | F5: STORAGE TYPE | G5: Climate Type | H5: DEHUMIDIFER | I5: NOKE
H6: YES / NO | I6: YES / NO
A7: MMR | B7: 1 | C7: W1000 | D7: TO | E7: W1108 | F7: W or WL | G7: Refrigerated | H7: NO | I7: NO
A8: MMR | B8: 2 | C8: W5001 | D8: TO | E8: W5039 | F8: W or WL | G8: Refrigerated | H8: NO | I8: NO
A9: MMR | B9: 3 | C9: A1000 | D9: TO | E9: A1071 | G9: AIRCON | H9: YES | I9: NO
A10: MMR | B10: 4 | C10: A1100 | D10: TO | E10: A1105 | G10: AIRCON | H10: NO | I10: NO
A11: MMR | B11: 5 | C11: M1000 | D11: TO | E11: M1179 | G11: AIRCON | H11: YES | I11: NO
A12: MMR | B12: 6 | C12: M1180 | D12: TO | E12: M1182 | G12: AIRCON | H12: NO | I12: NO
A13: MMR | B13: 7 | C13: 2200 | D13: TO | E13: 2295 | G13: AIRCON | H13: YES | I13: NO
A14: MMR | B14: 8 | C14: A5001 | D14: TO | E14: A5213 | G14: AIRCON | H14: YES | I14: NO
A15: MMR | B15: 9 | C15: 1200 | D15: TO | E15: 1215 | G15: NON AIRCON | H15: NO | I15: NO
A16: MMR | B16: 10 | C16: 1183M | D16: TO | E16: 1184M | G16: NON AIRCON | H16: NO | I16: NO
A17: MMR | B17: 11 | C17: 2000 | D17: TO | E17: 2303 | G17: NON AIRCON | H17: NO | I17: NO
A18: MMR | B18: 12 | C18: 3000 | D18: TO | E18: 3404 | G18: NON AIRCON | H18: NO | I18: NO
A19: MMR | B19: 13 | C19: 4000 | D19: TO | E19: 4400 | G19: NON AIRCON | H19: NO | I19: NO
A20: MMR | B20: 14 | C20: D1100 | D20: TO | E20: D1110 | G20: NON AIRCON | H20: NO | I20: NO

Sheet TS
B3: STORAGE UNITS DESCRIPTION IN TAI SENG
A5: Internal Name | B5: S/N | C5: UNITS Name Range | F5: STORAGE TYPE | G5: Climate Type | H5: DEHUMIDIFER | I5: NOKE
H6: YES / NO | I6: YES / NO
A7: TS | B7: 1 | C7: A2000 | D7: TO | E7: A2061 | G7: AIR-CON | H7: No | I7: Yes
A8: TS | B8: 2 | C8: A4000 | D8: TO | E8: A4077 | G8: AIR-CON | H8: No | I8: Yes
A9: TS | B9: 3 | C9: 5001 | D9: TO | E9: 5062 | G9: NON AIR-CON | H9: No | I9: No
A10: TS | B10: 4 | C10: A7000 | D10: TO | E10: A7076 | G10: AIR-CON | H10: No | I10: Yes

Sheet KWY
B3: STORAGE UNITS DESCRIPTION IN KALLANG WAY
A5: Internal Name | B5: S/N | C5: UNITS Name Range | F5: STORAGE TYPE | G5: Climate Type | H5: DEHUMIDIFER | I5: NOKE
H6: YES / NO | I6: YES / NO
A7: KWY | B7: 1 | C7: A1000 | D7: TO | E7: A1039 | G7: AIR-CON | H7: YES | I7: NO
A8: KWY | B8: 2 | C8: 1000 | D8: TO | E8: 1018 | G8: NON AIR-CON | H8: NO | I8: NO
A9: KWY | B9: 3 | C9: W1001 | D9: TO | E9: W1168 | F9: W or WL | G9: Refrigerated | H9: NO | I9: NO
A10: KWY | B10: 4 | C10: 2000 | D10: TO | E10: 2168 | G10: CLIMATE CONTROL | H10: NO | I10: NO
A11: KWY | B11: 5 | C11: 3000 | D11: TO | E11: 3147 | G11: NON AIR-CON | H11: NO | I11: YES
A12: KWY | B12: 6 | C12: 4001 | D12: TO | E12: 4218 | G12: NON AIR-CON | H12: NO | I12: NO
A13: KWY | B13: 7 | C13: A5001 | D13: TO | E13: A5044 | G13: AIR-CON | H13: NO | I13: NO
A14: KWY | B14: 8 | C14: 5045 | D14: TO | E14: 5216 | G14: NON AIR-CON | H14: NO | I14: NO
A15: KWY | B15: 9 | C15: 6001 | D15: TO | E15: 6166 | G15: CLIMATE CONTROL | H15: NO | I15: NO

Sheet YJ
B3: STORAGE UNITS DESCRIPTION IN YANGJAE
A5: Internal Name | B5: S/N | C5: UNITS Name Range | F5: STORAGE TYPE | G5: Climate Type | H5: DEHUMIDIFER | I5: NOKE
H6: YES / NO | I6: YES / NO
A7: YJ | B7: 1 | C7: H1001 | D7: TO | E7: H1100 | G7: AIR-CON, ONLY FOR SUMMER | H7: NO | I7: NO
A8: YJ | B8: 2 | C8: H1101 | D8: TO | E8: H1199 | G8: AIR-CON, ONLY FOR SUMMER | H8: NO | I8: NO
A9: YJ | B9: 3 | C9: H1200 | D9: TO | E9: H1299 | G9: AIR-CON, ONLY FOR SUMMER | H9: NO | I9: NO
A10: YJ | B10: 4 | C10: H1300 | D10: TO | E10: H1399 | G10: AIR-CON, ONLY FOR SUMMER | H10: NO | I10: NO
A11: YJ | B11: 5 | C11: H1400 | D11: TO | E11: H1436 | G11: AIR-CON, ONLY FOR SUMMER | H11: YES, ONLY FOR SUMMER | I11: NO
A12: YJ | B12: 6 | C12: H2001 | D12: TO | E12: H2101 | G12: AIR-CON, ONLY FOR SUMMER | H12: NO | I12: NO
B14: * During the summer season, dehumidifiers are operated on a limited basis near the sunken area to manage humidity levels.

Sheet BD
B3: STORAGE UNITS DESCRIPTION IN BUNDANG
A5: Internal Name | B5: S/N | C5: UNITS Name Range | F5: STORAGE TYPE | G5: Climate Type | H5: DEHUMIDIFER | I5: NOKE
H6: YES / NO | I6: YES / NO
A7: BD | B7: 1 | C7: B2001 | D7: TO | E7: B2019 | G7: AIR-CON, ONLY FOR SUMMER | H7: YES, ONLY FOR SUMMER | I7: NO
A8: BD | B8: 2 | C8: B1001 | D8: TO | E8: B1035 | G8: AIR-CON, ONLY FOR SUMMER | H8: YES, ONLY FOR SUMMER | I8: NO
A9: BD | B9: 3 | C9: 3001 | D9: TO | E9: 3169 | G9: AIR-CON, ONLY FOR SUMMER | H9: NO | I9: NO
A10: BD | B10: 4 | C10: 4001 | D10: TO | E10: 4149 | G10: AIR-CON, ONLY FOR SUMMER | H10: NO | I10: NO
A11: BD | B11: 5 | C11: 5001 | D11: TO | E11: 5077 | G11: AIR-CON, ONLY FOR SUMMER | H11: NO | I11: NO
B13: *During the summer season, dehumidifiers are operated on Basement Level 1 and Level 2 to manage humidity levels.

Sheet AGJ
B3: STORAGE UNITS DESCRIPTION IN APGUJEONG
A5: Internal Name | B5: S/N | C5: UNITS Name Range | F5: STORAGE TYPE | G5: Climate Type | H5: DEHUMIDIFER | I5: NOKE
H6: YES / NO | I6: YES / NO
A7: AGJ | B7: 1 | C7: 1001 | D7: TO | E7: 1378 | G7: AIR-CON, ONLY FOR SUMMER | H7: YES, ONLY FOR SUMMER | I7: NO
A8: AGJ | B8: 2
A9: AGJ | B9: 3
A10: AGJ | B10: 4
A11: AGJ | B11: 5
A12: AGJ | B12: 6
A13: AGJ | B13: 7
A14: AGJ | B14: 8
A15: AGJ | B15: 9

Sheet GS
B3: STORAGE UNITS DESCRIPTION IN GASAN
A5: Internal Name | B5: S/N | C5: UNITS Name Range | F5: STORAGE TYPE | G5: Climate Type | H5: DEHUMIDIFER | I5: NOKE
H6: YES / NO | I6: YES / NO
A7: GS | B7: 1 | C7: 1001 | D7: TO | E7: 1086 | G7: AIR-CON, ONLY FOR SUMMER | H7: NO | I7: NO
A8: GS | B8: 2
A9: GS | B9: 3
A10: GS | B10: 4
A11: GS | B11: 5
A12: GS | B12: 6
A13: GS | B13: 7
A14: GS | B14: 8
A15: GS | B15: 9

Sheet YDP
B3: STORAGE UNITS DESCRIPTION IN YEINGDEUNGPO
A5: Internal Name | B5: S/N | C5: UNITS Name Range | F5: STORAGE TYPE | G5: Climate Type | H5: DEHUMIDIFER | I5: NOKE
H6: YES / NO | I6: YES / NO
A7: YDP | B7: 1 | C7: 1001 | D7: TO | E7: 1079 | G7: AIR-CON, ONLY FOR SUMMER | H7: YES, ONLY FOR SUMMER | I7: NO
A8: YDP | B8: 2 | C8: 1080 | D8: TO | E8: 1086 | G8: NON AIR-CON | H8: YES, ONLY FOR SUMMER | I8: NO | K8: *It is a small, separate space without air conditioning; however, a dehumidifier is operated during the summer season.
A9: YDP | B9: 3
A10: YDP | B10: 4
A11: YDP | B11: 5
A12: YDP | B12: 6
A13: YDP | B13: 7
A14: YDP | B14: 8
A15: YDP | B15: 9

Sheet YS
B3: STORAGE UNITS DESCRIPTION IN YONGSAN
A5: Internal Name | B5: S/N | C5: UNITS Name Range | F5: STORAGE TYPE | G5: Climate Type | H5: DEHUMIDIFER | I5: NOKE
H6: YES / NO | I6: YES / NO
A7: YS | B7: 1 | C7: 2001 | D7: TO | E7: 2104 | G7: AIR-CON, ONLY FOR SUMMER | H7: NO | I7: NO
A8: YS | B8: 2
A9: YS | B9: 3
A10: YS | B10: 4
A11: YS | B11: 5
A12: YS | B12: 6
A13: YS | B13: 7
A14: YS | B14: 8
A15: YS | B15: 9

Sheet BP
B3: STORAGE UNITS DESCRIPTION IN BANPO
A5: Internal Name | B5: S/N | C5: UNITS Name Range | F5: STORAGE TYPE | G5: Climate Type | H5: DEHUMIDIFER | I5: NOKE
H6: YES / NO | I6: YES / NO
A7: BP | B7: 1 | C7: 1001 | D7: TO | E7: 1063 | G7: AIR-CON, ONLY FOR SUMMER | H7: NO | I7: NO
A8: BP | B8: 2
A9: BP | B9: 3
A10: BP | B10: 4
A11: BP | B11: 5
A12: BP | B12: 6
A13: BP | B13: 7
A14: BP | B14: 8
A15: BP | B15: 9

Sheet CSL
B3: STORAGE UNITS DESCRIPTION IN CHAN SOW LIN
A5: Internal Name | B5: S/N | C5: UNITS Name Range | F5: STORAGE TYPE | G5: Climate Type | H5: DEHUMIDIFER | I5: NOKE
H6: YES / NO | I6: YES / NO
A7: CSL | B7: 1 | C7: G0001 | D7: TO | E7: G1110 | G7: NON AIR-CON | H7: NO | I7: NO
A8: CSL | B8: 2 | C8: OG03 | D8: TO | E8: OG03 | G8: NON AIR-CON | H8: NO | I8: NO
A9: CSL | B9: 3 | C9: 2000 | D9: TO | E9: 2373 | G9: NON AIR-CON | H9: NO | I9: NO
A10: CSL | B10: 4 | C10: 3003 | D10: TO | E10: 3281 | G10: NON AIR-CON | H10: NO | I10: NO
A11: CSL | B11: 5 | C11: 4002 | D11: TO | E11: 4260 | G11: NON AIR-CON | H11: NO | I11: NO
A12: CSL | B12: 6 | C12: A3000 | D12: TO | E12: A3180 | G12: AIR-CON | H12: NO | I12: NO
A13: CSL | B13: 7 | C13: W3000 | D13: TO | E13: W3019 | F13: W or WL | G13: Refrigerated | H13: NO | I13: NO

Sheet SEG
B3: STORAGE UNITS DESCRIPTION IN SEGAMBUT
A5: Internal Name | B5: S/N | C5: UNITS Name Range | F5: STORAGE TYPE | G5: Climate Type | H5: DEHUMIDIFER | I5: NOKE
H6: YES / NO | I6: YES / NO
A7: SEG | B7: 1 | C7: G1001 | D7: TO | E7: G1403 | G7: NON AIR-CON | H7: NO | I7: NO
A8: SEG | B8: 2 | C8: 1001 | D8: TO | E8: 1685 | G8: NON AIR-CON | H8: NO | I8: NO
A9: SEG | B9: 3 | C9: A1201 | D9: TO | E9: A1608 | G9: AIR-CON | H9: NO | I9: NO

Sheet S51
B3: STORAGE UNITS DESCRIPTION IN S51A
A5: Internal Name | B5: S/N | C5: UNITS Name Range | F5: STORAGE TYPE | G5: Climate Type | H5: DEHUMIDIFER | I5: NOKE
H6: YES / NO | I6: YES / NO
A7: S51 | B7: 1 | C7: G1001 | D7: TO | E7: G1198 | G7: NON AIR-CON | H7: NO | I7: NO
A8: S51 | B8: 2 | C8: OG02 | D8: TO | E8: OG02 | G8: NON AIR-CON | H8: NO | I8: NO
A9: S51 | B9: 3 | C9: 1001 | D9: TO | E9: 1118 | G9: NON AIR-CON | H9: NO | I9: NO
A10: S51 | B10: 4 | C10: C1001 | D10: TO | E10: C1021 | G10: NON AIR-CON | H10: NO | I10: NO
A11: S51 | B11: 5 | C11: 2001 | D11: TO | E11: 2186 | G11: NON AIR-CON | H11: NO | I11: NO
A12: S51 | B12: 6 | C12: C2001 | D12: TO | E12: C2021 | G12: NON AIR-CON | H12: NO | I12: NO
A13: S51 | B13: 7 | C13: A1001 | D13: TO | E13: A1181 | G13: AIR-CON | H13: NO | I13: NO
A14: S51 | B14: 8 | C14: W0001 | D14: TO | E14: W1017 | F14: W or WL | G14: Refrigerated | H14: NO | I14: NO
A15: S51 | B15: 9 | C15: L1001 | D15: TO | E15: L1106 | F15: Drive UP | G15: NON AIR-CON | H15: NO | I15: NO
A16: S51 | B16: 10 | C16: T1001 | D16: TO | E16: T1006 | F16: Drive UP | G16: NON AIR-CON | H16: NO | I16: NO
A17: S51 | B17: 11 | C17: B1001 | D17: TO | E17: B1069 | F17: Drive UP | G17: NON AIR-CON | H17: NO | I17: NO

Sheet KD
B3: STORAGE UNITS DESCRIPTION IN KOTA DAMANSARA
A5: Internal Name | B5: S/N | C5: UNITS Name Range | F5: STORAGE TYPE | G5: Climate Type | H5: DEHUMIDIFER | I5: NOKE
H6: YES / NO | I6: YES / NO
A7: KD | B7: 1 | C7: 3001 | D7: TO | E7: 3220 | G7: NON AIR-CON | H7: NO | I7: NO
A8: KD | B8: 2 | C8: 5001 | D8: TO | E8: 5334 | G8: NON AIR-CON | H8: NO | I8: NO
